{
 "cells": [
  {
   "cell_type": "markdown",
   "metadata": {},
   "source": [
    "# Manejo de errores y excepciones\n",
    "\n",
    "### Errores\n",
    "\n",
    "En un programa podemos encontrarnos con distintos tipos de errores pero a grandes rasgos podemos decir que todos los errores pertenecen a una de las siguientes categorías.\n",
    "\n",
    "- **Errores de sintaxis:** estos errores son seguramente los más simples de resolver, pues son detectados por el intérprete (o por el compilador, según el tipo de lenguaje que estemos utilizando) al procesar el código fuente y generalmente son consecuencia de equivocaciones al escribir el programa. En el caso de Python estos errores son indicados con un mensaje SyntaxError. Por ejemplo, si trabajando con Python intentamos definir una función y en lugar de def escribimos dev.\n",
    "\n",
    "- **Errores semánticos:** se dan cuando un programa, a pesar de no generar mensajes de error, no produce el resultado esperado. Esto puede deberse, por ejemplo, a un algoritmo incorrecto o a la omisión de una sentencia.\n",
    "\n",
    "- **Errores de ejecución:** estos errores aparecen durante la ejecución del programa y su origen puede ser diverso. En ocasiones pueden producirse por un uso incorrecto del programa por parte del usuario, por ejemplo si el usuario ingresa una cadena cuando se espera un número. En otras ocasiones pueden deberse a errores de programación, por ejemplo si una función intenta acceder a la quinta posición de una lista de 3 elementos o realizar una división por cero. Una causa común de errores de ejecución que generalmente excede al programador y al usuario, son los recursos externos al programa, por ejemplo si el programa intenta leer un archivo y el mismo se encuentra dañado.\n",
    "\n",
    "Tanto a los errores de sintaxis como a los semánticos se los puede detectar y corregir durante la construcción del programa ayudados por el intérprete y la ejecución de pruebas. Pero no ocurre esto con los errores de ejecución ya que no siempre es posible saber cuando ocurrirán y puede resultar muy complejo (o incluso casi imposible) reproducirlos. Es por ello que el resto de la unidad nos centraremos en cómo preparar nuestros programas para lidiar con este tipo de errores."
   ]
  },
  {
   "cell_type": "markdown",
   "metadata": {},
   "source": [
    "### Excepciones\n",
    "\n",
    "Los errores de ejecución son llamados comúnmente excepciones y por eso de ahora en más utilizaremos ese nombre. Durante la ejecución de un programa, si dentro de una función surge una excepción y la función no la maneja, la excepción se propaga hacia la función que la invocó, si esta otra tampoco la maneja, la excepción continua propagándose hasta llegar a la función inicial del programa y si esta tampoco la maneja se interrumpe la ejecución del programa. Veamos entonces como manejar excepciones.\n",
    "\n",
    "#### Manejo de excepciones\n",
    "\n",
    "Para el manejo de excepciones los lenguajes proveen ciertas palabras reservadas, que nos permiten manejar las excepciones que puedan surgir y tomar acciones de recuperación para evitar la interrupción del programa o, al menos, para realizar algunas acciones adicionales antes de interrumpir el programa.\n",
    "\n",
    "En el caso de Python, el manejo de excepciones se hace mediante los bloques que utilizan las sentencias **try**, **except** y **finally**.\n",
    "\n",
    "Dentro del bloque try se ubica todo el código que pueda llegar a levantar una excepción, se utiliza el término levantar para referirse a la acción de generar una excepción.\n",
    "\n",
    "A continuación se ubica el bloque except, que se encarga de capturar la excepción y nos da la oportunidad de procesarla mostrando por ejemplo un mensaje adecuado al usuario. Veamos qué sucede si se quiere realizar una división por cero:"
   ]
  },
  {
   "cell_type": "code",
   "execution_count": 1,
   "metadata": {
    "collapsed": false
   },
   "outputs": [
    {
     "ename": "ZeroDivisionError",
     "evalue": "division by zero",
     "output_type": "error",
     "traceback": [
      "\u001b[0;31m---------------------------------------------------------------------------\u001b[0m",
      "\u001b[0;31mZeroDivisionError\u001b[0m                         Traceback (most recent call last)",
      "\u001b[0;32m<ipython-input-1-e22959b81d50>\u001b[0m in \u001b[0;36m<module>\u001b[0;34m()\u001b[0m\n\u001b[1;32m      1\u001b[0m \u001b[0mdividendo\u001b[0m \u001b[0;34m=\u001b[0m \u001b[0;36m8\u001b[0m\u001b[0;34m\u001b[0m\u001b[0m\n\u001b[1;32m      2\u001b[0m \u001b[0mdivisor\u001b[0m \u001b[0;34m=\u001b[0m \u001b[0;36m0\u001b[0m\u001b[0;34m\u001b[0m\u001b[0m\n\u001b[0;32m----> 3\u001b[0;31m \u001b[0mcociente\u001b[0m \u001b[0;34m=\u001b[0m \u001b[0mdividendo\u001b[0m \u001b[0;34m/\u001b[0m \u001b[0mdivisor\u001b[0m\u001b[0;34m\u001b[0m\u001b[0m\n\u001b[0m",
      "\u001b[0;31mZeroDivisionError\u001b[0m: division by zero"
     ]
    }
   ],
   "source": [
    "dividendo = 8\n",
    "divisor = 0\n",
    "cociente = dividendo / divisor"
   ]
  },
  {
   "cell_type": "markdown",
   "metadata": {},
   "source": [
    "En este caso, se levantó la excepción **ZeroDivisionError** cuando se quiso hacer la división. Para evitar que se levante la excepción y se detenga la ejecución del programa, se utiliza el bloque **try-except**."
   ]
  },
  {
   "cell_type": "code",
   "execution_count": 2,
   "metadata": {
    "collapsed": false
   },
   "outputs": [
    {
     "name": "stdout",
     "output_type": "stream",
     "text": [
      "No se pudo efectuar la division\n"
     ]
    }
   ],
   "source": [
    "try:\n",
    "    cociente = dividendo / divisor\n",
    "except:\n",
    "    print(\"No se pudo efectuar la division\")"
   ]
  },
  {
   "cell_type": "markdown",
   "metadata": {},
   "source": [
    "Tambíen podemos capturar multiples excepciones mediante la estrcutura:"
   ]
  },
  {
   "cell_type": "code",
   "execution_count": 3,
   "metadata": {
    "collapsed": false
   },
   "outputs": [
    {
     "ename": "IndentationError",
     "evalue": "expected an indented block (<ipython-input-3-711f473ffa9f>, line 3)",
     "output_type": "error",
     "traceback": [
      "\u001b[0;36m  File \u001b[0;32m\"<ipython-input-3-711f473ffa9f>\"\u001b[0;36m, line \u001b[0;32m3\u001b[0m\n\u001b[0;31m    except IOError:\u001b[0m\n\u001b[0m         ^\u001b[0m\n\u001b[0;31mIndentationError\u001b[0m\u001b[0;31m:\u001b[0m expected an indented block\n"
     ]
    }
   ],
   "source": [
    "try:\n",
    "    # aquí ponemos el código que puede lanzar excepciones\n",
    "except IOError:\n",
    "    # entrará aquí en caso que se haya producido una excepción IOError\n",
    "except ZeroDivisionError:\n",
    "    # entrará aquí en caso que se haya producido una excepción ZeroDivisionError\n",
    "except:    \n",
    "    # entrará aquí en caso que se haya producido una excepción que no corresponda a ninguno\n",
    "    # de los tipos especificados en los except previos"
   ]
  },
  {
   "cell_type": "code",
   "execution_count": 4,
   "metadata": {
    "collapsed": false
   },
   "outputs": [
    {
     "name": "stdout",
     "output_type": "stream",
     "text": [
      "Ingrese un número: \n",
      "Ingresa un número válido\n",
      "Ingrese un número: 0\n",
      "Pero que el número no sea cero!\n",
      "Ingrese un número: 3\n",
      "12 / 3 = 4.0\n"
     ]
    }
   ],
   "source": [
    "while True:\n",
    "    try:\n",
    "        num_str = input('Ingrese un número: ')\n",
    "        num = int(num_str)\n",
    "        print(\"{} / {} = {}\".format(12,num, 12/num ))\n",
    "        break\n",
    "    except ValueError:\n",
    "        print('Ingresa un número válido')\n",
    "    except ZeroDivisionError:\n",
    "        print('Pero que el número no sea cero!')"
   ]
  },
  {
   "cell_type": "markdown",
   "metadata": {},
   "source": [
    "Finalmente, puede ubicarse un bloque **finally** donde se escriben las sentencias de finalización, que son típicamente acciones de limpieza. La particularidad del bloque finally es que se ejecuta siempre, haya surgido una excepción o no. Si hay un bloque except, no es necesario que esté presente el finally, y es posible tener un bloque try sólo con finally, sin except."
   ]
  },
  {
   "cell_type": "code",
   "execution_count": 5,
   "metadata": {
    "collapsed": false
   },
   "outputs": [
    {
     "name": "stdout",
     "output_type": "stream",
     "text": [
      "No pude convertir el dato a un entero.\n",
      "Ha terminado el bloque\n"
     ]
    }
   ],
   "source": [
    "import sys\n",
    "\n",
    "try:\n",
    "    f = open('miarchivo.txt')\n",
    "    s = f.readline()\n",
    "    i = int(s.strip())\n",
    "except OSError as err:\n",
    "    print(\"Error OS: {0}\".format(err))\n",
    "except ValueError:\n",
    "    print(\"No pude convertir el dato a un entero.\")\n",
    "except:\n",
    "    print(\"Error inesperado:\", sys.exc_info()[0])\n",
    "finally:\n",
    "    print(\"Ha terminado el bloque\")"
   ]
  },
  {
   "cell_type": "markdown",
   "metadata": {},
   "source": [
    "### Levantando excepciones"
   ]
  },
  {
   "cell_type": "markdown",
   "metadata": {},
   "source": [
    "La declaración **raise** permite al programador forzar a que ocurra una excepción específica. Por ejemplo:"
   ]
  },
  {
   "cell_type": "code",
   "execution_count": 6,
   "metadata": {
    "collapsed": false
   },
   "outputs": [
    {
     "ename": "NameError",
     "evalue": "How you doing?",
     "output_type": "error",
     "traceback": [
      "\u001b[0;31m---------------------------------------------------------------------------\u001b[0m",
      "\u001b[0;31mNameError\u001b[0m                                 Traceback (most recent call last)",
      "\u001b[0;32m<ipython-input-6-f5dee82ee479>\u001b[0m in \u001b[0;36m<module>\u001b[0;34m()\u001b[0m\n\u001b[0;32m----> 1\u001b[0;31m \u001b[0;32mraise\u001b[0m \u001b[0mNameError\u001b[0m\u001b[0;34m(\u001b[0m\u001b[0;34m'How you doing?'\u001b[0m\u001b[0;34m)\u001b[0m\u001b[0;34m\u001b[0m\u001b[0m\n\u001b[0m",
      "\u001b[0;31mNameError\u001b[0m: How you doing?"
     ]
    }
   ],
   "source": [
    "raise NameError('How you doing?')"
   ]
  },
  {
   "cell_type": "markdown",
   "metadata": {},
   "source": [
    "El único argumento a raise indica la excepción a generarse. Tiene que ser o una instancia de excepción, o una clase de excepción (una clase que hereda de Exception).\n",
    "\n",
    "Si necesitás determinar cuando una excepción fue lanzada pero no querés manejarla, una forma simplificada de la instrucción raise te permite relanzarla:"
   ]
  },
  {
   "cell_type": "code",
   "execution_count": 7,
   "metadata": {
    "collapsed": false
   },
   "outputs": [
    {
     "name": "stdout",
     "output_type": "stream",
     "text": [
      "Acaba de ocurrir una excepción!\n"
     ]
    },
    {
     "ename": "NameError",
     "evalue": "I am fine",
     "output_type": "error",
     "traceback": [
      "\u001b[0;31m---------------------------------------------------------------------------\u001b[0m",
      "\u001b[0;31mNameError\u001b[0m                                 Traceback (most recent call last)",
      "\u001b[0;32m<ipython-input-7-d3cfc816c189>\u001b[0m in \u001b[0;36m<module>\u001b[0;34m()\u001b[0m\n\u001b[1;32m      1\u001b[0m \u001b[0;32mtry\u001b[0m\u001b[0;34m:\u001b[0m\u001b[0;34m\u001b[0m\u001b[0m\n\u001b[0;32m----> 2\u001b[0;31m     \u001b[0;32mraise\u001b[0m \u001b[0mNameError\u001b[0m\u001b[0;34m(\u001b[0m\u001b[0;34m'I am fine'\u001b[0m\u001b[0;34m)\u001b[0m\u001b[0;34m\u001b[0m\u001b[0m\n\u001b[0m\u001b[1;32m      3\u001b[0m \u001b[0;32mexcept\u001b[0m \u001b[0mNameError\u001b[0m\u001b[0;34m:\u001b[0m\u001b[0;34m\u001b[0m\u001b[0m\n\u001b[1;32m      4\u001b[0m     \u001b[0mprint\u001b[0m\u001b[0;34m(\u001b[0m\u001b[0;34m'Acaba de ocurrir una excepción!'\u001b[0m\u001b[0;34m)\u001b[0m\u001b[0;34m\u001b[0m\u001b[0m\n\u001b[1;32m      5\u001b[0m     \u001b[0;32mraise\u001b[0m\u001b[0;34m\u001b[0m\u001b[0m\n",
      "\u001b[0;31mNameError\u001b[0m: I am fine"
     ]
    }
   ],
   "source": [
    "try:\n",
    "    raise NameError('I am fine')\n",
    "except NameError:\n",
    "    print('Acaba de ocurrir una excepción!')\n",
    "    raise"
   ]
  },
  {
   "cell_type": "markdown",
   "metadata": {},
   "source": [
    "De más está decir, que las excepciones pueden ser personalizadas según sea necesario:"
   ]
  },
  {
   "cell_type": "code",
   "execution_count": 8,
   "metadata": {
    "collapsed": false
   },
   "outputs": [
    {
     "name": "stdout",
     "output_type": "stream",
     "text": [
      "Error creado: Archivos inválidos  ('a.conf', 'b.conf')\n"
     ]
    }
   ],
   "source": [
    "class MiError(Exception):\n",
    "    \n",
    "    def __init__(self, mssg, ref=''):\n",
    "        self.mssg = mssg\n",
    "        self.ref = ref\n",
    "    \n",
    "    def __str__(self,):\n",
    "        return \"Error creado: {}  {}\".format(self.mssg, self.ref)\n",
    "    \n",
    "try:\n",
    "    raise MiError(\"Archivos inválidos\", ('a.conf','b.conf') )\n",
    "except MiError as e:\n",
    "    print(e)"
   ]
  }
 ],
 "metadata": {
  "kernelspec": {
   "display_name": "Python 3",
   "language": "python",
   "name": "python3"
  },
  "language_info": {
   "codemirror_mode": {
    "name": "ipython",
    "version": 3
   },
   "file_extension": ".py",
   "mimetype": "text/x-python",
   "name": "python",
   "nbconvert_exporter": "python",
   "pygments_lexer": "ipython3",
   "version": "3.5.2"
  }
 },
 "nbformat": 4,
 "nbformat_minor": 1
}
